{
    "type": "error",
    "data": "Error executing verb \"extract_graph\" in extract_graph: \"Column(s) ['description', 'source_id', 'weight'] do not exist\"",
    "stack": "Traceback (most recent call last):\n  File \"/usr/local/lib/python3.10/dist-packages/datashaper/workflow/workflow.py\", line 415, in _execute_verb\n    result = await result\n  File \"/workspace/graphrag/index/workflows/v1/extract_graph.py\", line 92, in workflow\n    base_entity_nodes, base_relationship_edges = await extract_graph(\n  File \"/workspace/graphrag/index/flows/extract_graph.py\", line 35, in extract_graph\n    entities, relationships = await extract_entities(\n  File \"/workspace/graphrag/index/operations/extract_entities/extract_entities.py\", line 142, in extract_entities\n    relationships = _merge_relationships(relationship_dfs)\n  File \"/workspace/graphrag/index/operations/extract_entities/extract_entities.py\", line 182, in _merge_relationships\n    all_relationships.groupby([\"source\", \"target\"], sort=False)\n  File \"/usr/local/lib/python3.10/dist-packages/pandas/core/groupby/generic.py\", line 1432, in aggregate\n    result = op.agg()\n  File \"/usr/local/lib/python3.10/dist-packages/pandas/core/apply.py\", line 190, in agg\n    return self.agg_dict_like()\n  File \"/usr/local/lib/python3.10/dist-packages/pandas/core/apply.py\", line 423, in agg_dict_like\n    return self.agg_or_apply_dict_like(op_name=\"agg\")\n  File \"/usr/local/lib/python3.10/dist-packages/pandas/core/apply.py\", line 1608, in agg_or_apply_dict_like\n    result_index, result_data = self.compute_dict_like(\n  File \"/usr/local/lib/python3.10/dist-packages/pandas/core/apply.py\", line 462, in compute_dict_like\n    func = self.normalize_dictlike_arg(op_name, selected_obj, func)\n  File \"/usr/local/lib/python3.10/dist-packages/pandas/core/apply.py\", line 663, in normalize_dictlike_arg\n    raise KeyError(f\"Column(s) {list(cols)} do not exist\")\nKeyError: \"Column(s) ['description', 'source_id', 'weight'] do not exist\"\n",
    "source": "\"Column(s) ['description', 'source_id', 'weight'] do not exist\"",
    "details": null
}
{
    "type": "error",
    "data": "Error running pipeline!",
    "stack": "Traceback (most recent call last):\n  File \"/workspace/graphrag/index/run/run.py\", line 262, in run_pipeline\n    result = await _process_workflow(\n  File \"/workspace/graphrag/index/run/workflow.py\", line 107, in _process_workflow\n    result = await workflow.run(context, callbacks)\n  File \"/usr/local/lib/python3.10/dist-packages/datashaper/workflow/workflow.py\", line 369, in run\n    timing = await self._execute_verb(node, context, callbacks)\n  File \"/usr/local/lib/python3.10/dist-packages/datashaper/workflow/workflow.py\", line 415, in _execute_verb\n    result = await result\n  File \"/workspace/graphrag/index/workflows/v1/extract_graph.py\", line 92, in workflow\n    base_entity_nodes, base_relationship_edges = await extract_graph(\n  File \"/workspace/graphrag/index/flows/extract_graph.py\", line 35, in extract_graph\n    entities, relationships = await extract_entities(\n  File \"/workspace/graphrag/index/operations/extract_entities/extract_entities.py\", line 142, in extract_entities\n    relationships = _merge_relationships(relationship_dfs)\n  File \"/workspace/graphrag/index/operations/extract_entities/extract_entities.py\", line 182, in _merge_relationships\n    all_relationships.groupby([\"source\", \"target\"], sort=False)\n  File \"/usr/local/lib/python3.10/dist-packages/pandas/core/groupby/generic.py\", line 1432, in aggregate\n    result = op.agg()\n  File \"/usr/local/lib/python3.10/dist-packages/pandas/core/apply.py\", line 190, in agg\n    return self.agg_dict_like()\n  File \"/usr/local/lib/python3.10/dist-packages/pandas/core/apply.py\", line 423, in agg_dict_like\n    return self.agg_or_apply_dict_like(op_name=\"agg\")\n  File \"/usr/local/lib/python3.10/dist-packages/pandas/core/apply.py\", line 1608, in agg_or_apply_dict_like\n    result_index, result_data = self.compute_dict_like(\n  File \"/usr/local/lib/python3.10/dist-packages/pandas/core/apply.py\", line 462, in compute_dict_like\n    func = self.normalize_dictlike_arg(op_name, selected_obj, func)\n  File \"/usr/local/lib/python3.10/dist-packages/pandas/core/apply.py\", line 663, in normalize_dictlike_arg\n    raise KeyError(f\"Column(s) {list(cols)} do not exist\")\nKeyError: \"Column(s) ['description', 'source_id', 'weight'] do not exist\"\n",
    "source": "\"Column(s) ['description', 'source_id', 'weight'] do not exist\"",
    "details": null
}
